return next(err) does not cut off rest of promise chain as expected
